<?xml version="1.0" ?>
<!-- =================================================================================== -->
<!-- |    This document was autogenerated by xacro from /home/fandes/workspace/kuavo-ros-control/src/humanoid-control/humanoid_interface_drake/models/biped_gen4.0/urdf/biped_v3_all_joint.xacro | -->
<!-- |    EDITING THIS FILE BY HAND IS NOT RECOMMENDED                                 | -->
<!-- =================================================================================== -->
<robot name="biped_v3_all_joint" xmlns:drake="https://drake.mit.edu">
  <link name="torso">
    <inertial>
      <origin xyz="-0.00505 0.0014 0.18077" rpy="0 0 0" />
      <mass value="21.8652" />
      <inertia ixx="0.28214" ixy="3e-05" ixz="0.01114" iyy="0.20534" iyz="0.00044" izz="0.13735" />
    </inertial>
    <visual>
      <origin xyz="0 0 0" rpy="0 0 0" />
      <geometry>
        <mesh filename="../../meshes/base_link.STL" />
      </geometry>
      <material name="">
        <color rgba="1 1 1 1" />
      </material>
    </visual>
    <!-- <collision>
      <origin xyz="0 0 0" rpy="0 0 0" />
      <geometry>
        <mesh filename="../../meshes/base_link.STL" />
      </geometry>
    </collision> -->
  </link>
  <link name="leg_l1_link">
    <inertial>
      <origin xyz="-0.00540552 0.0 -0.00369091" rpy="0 0 0" />
      <mass value="1.79455987" />
      <inertia ixx="0.00210976" ixy="1e-06" ixz="0.0001804" iyy="0.00298913" iyz="-8e-08" izz="0.00395154" />
    </inertial>
    <visual>
      <origin xyz="0 0 0" rpy="0 0 0" />
      <geometry>
        <mesh filename="../../meshes/l_leg_roll.STL" />
      </geometry>
      <material name="">
        <color rgba="1 1 1 1" />
      </material>
    </visual>
  </link>
  <joint name="leg_l1_joint" type="revolute">
    <origin xyz="-0.0025 0.087 -0.066" rpy="0 0 0" />
    <parent link="torso" />
    <child link="leg_l1_link" />
    <axis xyz="1 0 0" />
    <limit lower="-0.314159265358979" upper="0.663225115757845" effort="180.0" velocity="23.55" />
  </joint>
  <transmission type="SimpleTransmission">
    <joint name="leg_l1_joint" />
    <actuator name="leg_l1_joint_motor" />
  </transmission>
  <link name="leg_l2_link">
    <inertial>
      <origin xyz="-0.0059853 0.01780742 -0.0711802" rpy="0 0 0" />
      <mass value="0.44959459" />
      <inertia ixx="0.00182951" ixy="6.31e-06" ixz="-3.379e-05" iyy="0.00079345" iyz="7.485e-05" izz="0.00142992" />
    </inertial>
    <visual>
      <origin xyz="0 0 0" rpy="0 0 0" />
      <geometry>
        <mesh filename="../../meshes/l_leg_yaw.STL" />
      </geometry>
      <material name="">
        <color rgba="1 1 1 1" />
      </material>
    </visual>
  </link>
  <joint name="leg_l2_joint" type="revolute">
    <origin xyz="0 0 0" rpy="0 0 0" />
    <parent link="leg_l1_link" />
    <child link="leg_l2_link" />
    <axis xyz="0 0 1" />
    <limit lower="-1.0471975511966" upper="0.523598775598299" effort="100.0" velocity="41.3433333333333" />
  </joint>
  <transmission type="SimpleTransmission">
    <joint name="leg_l2_joint" />
    <actuator name="leg_l2_joint_motor" />
  </transmission>
  <link name="leg_l3_link">
    <inertial>
      <origin xyz="-0.00144817 0.00270737 -0.10124151" rpy="0 0 0" />
      <mass value="6.69326562" />
      <inertia ixx="0.09123938" ixy="0.00044201" ixz="0.0029849" iyy="0.09330391" iyz="-0.00021264" izz="0.01705855" />
    </inertial>
    <visual>
      <origin xyz="0 0 0" rpy="0 0 0" />
      <geometry>
        <mesh filename="../../meshes/l_leg_pitch.STL" />
      </geometry>
      <material name="">
        <color rgba="1 1 1 1" />
      </material>
    </visual>
  </link>
  <joint name="leg_l3_joint" type="revolute">
    <origin xyz="0 0 -0.124999999999996" rpy="0 0 0" />
    <parent link="leg_l2_link" />
    <child link="leg_l3_link" />
    <axis xyz="0 1 0" />
    <limit lower="-1.83259571459405" upper="1.0471975511966" effort="100.0" velocity="41.3433333333333" />
  </joint>
  <transmission type="SimpleTransmission">
    <joint name="leg_l3_joint" />
    <actuator name="leg_l3_joint_motor" />
  </transmission>
  <link name="leg_l4_link">
    <inertial>
      <origin xyz="-0.00940804 -0.00020026 -0.1566321" rpy="0 0 0" />
      <mass value="2.29375237" />
      <inertia ixx="0.03340685" ixy="-1.739e-05" ixz="-0.00306822" iyy="0.03407041" iyz="-0.00021711" izz="0.00201364" />
    </inertial>
    <visual>
      <origin xyz="0 0 0" rpy="0 0 0" />
      <geometry>
        <mesh filename="../../meshes/l_knee.STL" />
      </geometry>
      <material name="">
        <color rgba="1 1 1 1" />
      </material>
    </visual>
  </link>
  <joint name="leg_l4_joint" type="revolute">
    <origin xyz="0.0419999999999991 0 -0.371446748811991" rpy="0 0 0" />
    <parent link="leg_l3_link" />
    <child link="leg_l4_link" />
    <axis xyz="0 1 0" />
    <limit lower="0.0" upper="2.00712863979348" effort="180.0" velocity="23.55" />
  </joint>
  <transmission type="SimpleTransmission">
    <joint name="leg_l4_joint" />
    <actuator name="leg_l4_joint_motor" />
  </transmission>
  <link name="leg_l5_link">
    <inertial>
      <origin xyz="0.0 0.0 0.0" rpy="0 0 0" />
      <mass value="0.07193524" />
      <inertia ixx="6.92e-06" ixy="0.0" ixz="0.0" iyy="6.92e-06" iyz="0.0" izz="1.218e-05" />
    </inertial>
    <visual>
      <origin xyz="0 0 0" rpy="0 0 0" />
      <geometry>
        <mesh filename="../../meshes/l_foot_pitch.STL" />
      </geometry>
      <material name="">
        <color rgba="1 1 1 1" />
      </material>
    </visual>
  </link>
  <joint name="leg_l5_joint" type="revolute">
    <origin xyz="0 0 -0.446000000000003" rpy="0 0 0" />
    <parent link="leg_l4_link" />
    <child link="leg_l5_link" />
    <axis xyz="0 1 0" />
    <limit lower="-0.567232006898157" upper="0.375245789178781" effort="36.0" velocity="23.0266666666667" />
  </joint>
  <transmission type="SimpleTransmission">
    <joint name="leg_l5_joint" />
    <actuator name="leg_l5_joint_motor" />
  </transmission>
  <link name="leg_l6_link">
    <inertial>
      <origin xyz="-0.0129597 -7.73e-06 -0.03296708" rpy="0 0 0" />
      <mass value="0.57421229" />
      <inertia ixx="0.00069693" ixy="1.4e-07" ixz="0.00046328" iyy="0.00226786" iyz="-3e-08" izz="0.00232583" />
    </inertial>
    <visual>
      <origin xyz="0 0 0" rpy="0 0 0" />
      <geometry>
        <mesh filename="../../meshes/l_foot_roll.STL" />
      </geometry>
      <material name="">
        <color rgba="1 1 1 1" />
      </material>
    </visual>
  </link>
  <joint name="leg_l6_joint" type="revolute">
    <origin xyz="0 0 0" rpy="0 0 0" />
    <parent link="leg_l5_link" />
    <child link="leg_l6_link" />
    <axis xyz="1 0 0" />
    <limit lower="-0.349065850398866" upper="0.349065850398866" effort="36.0" velocity="23.0266666666667" />
  </joint>
  <transmission type="SimpleTransmission">
    <joint name="leg_l6_joint" />
    <actuator name="leg_l6_joint_motor" />
  </transmission>
  <!-- sssssssss -->
  <link name="l_l_bar_y">
    <inertial>
      <origin rpy="0 0 0" xyz="-0.017639 -0.0012332 0.0047224"/>
      <mass value="0.041379"/>
      <inertia ixx="6.3487E-06" ixy="-2.7168E-06" ixz="4.9324E-06" iyy="2.8379E-05" iyz="7.2737E-07" izz="2.3451E-05"/>
    </inertial>
    <visual>
      <origin rpy="0 0 0" xyz="0 0 0"/>
      <geometry>
        <mesh filename="../../meshes/l_l_bar.STL"/>
      </geometry>
      <material name="">
        <color rgba="0.6902 0.65882 0.63922 1"/>
      </material>
    </visual>
    <!-- <collision>
      <origin xyz="0 0 0" rpy="0 0 0" />
      <geometry>
        <mesh filename="../../meshes/l_l_bar.STL" />
      </geometry>
    </collision> -->
  </link>
  <joint name="l_l_bar_y" type="continuous">
    <origin rpy="0 0 0" xyz="0 0.0318 -0.09"/>
    <parent link="leg_l4_link"/>
    <child link="l_l_bar_y"/>
    <axis xyz="0 1 0"/>
    <!-- <limit lower="-1.58" upper="0.50" effort="74" velocity="47" /> -->
  </joint>
  <transmission type="SimpleTransmission">
    <joint name="l_l_bar_y"/>
    <actuator name="l_l_bar_y_motor">
      <drake:gear_ratio value="10.0"/>
      <drake:rotor_inertia value="0.0001002"/>
    </actuator>
  </transmission>
  <link name="l_l_tendon_y">
    <inertial>
      <origin rpy="0 0 0" xyz="-1.3642E-05 -0.00048331 -0.13953"/>
      <mass value="0.13223"/>
      <inertia ixx="0.00049161" ixy="3.0645E-12" ixz="1.52E-08" iyy="0.00048973" iyz="-2.4263E-07" izz="4.775E-06"/>
    </inertial>
    <visual>
      <origin rpy="0 0 0" xyz="0 0 0"/>
      <geometry>
        <mesh filename="../../meshes/l_l_tendon.STL"/>
      </geometry>
      <material name="">
        <color rgba="0.6902 0.65882 0.63922 1"/>
      </material>
    </visual>
    <!-- <collision>
      <origin xyz="0 0 0" rpy="0 0 0" />
      <geometry>
        <mesh filename="../../meshes/l_l_tendon.STL" />
      </geometry>
    </collision> -->
  </link>
  <drake:joint name="l_l_tendon_y" type="universal">
    <origin rpy="0 0 0" xyz="-0.056027 -0.0085 0.015"/>
    <parent link="l_l_bar_y"/>
    <child link="l_l_tendon_y"/>
  </drake:joint>
  <frame link="l_l_tendon_y" name="l_l_tendon_socket" xyz="0 0 -0.256"/>
  <link name="l_r_bar_y">
    <inertial>
      <origin rpy="0 0 0" xyz="-0.017639 0.0012332 0.0047224"/>
      <mass value="0.041379"/>
      <inertia ixx="6.3486E-06" ixy="2.7168E-06" ixz="4.9323E-06" iyy="2.8379E-05" iyz="-7.2736E-07" izz="2.3451E-05"/>
    </inertial>
    <visual>
      <origin rpy="0 0 0" xyz="0 0 0"/>
      <geometry>
        <mesh filename="../../meshes/l_r_bar.STL"/>
      </geometry>
      <material name="">
        <color rgba="0.6902 0.65882 0.63922 1"/>
      </material>
    </visual>
    <!-- <collision>
      <origin xyz="0 0 0" rpy="0 0 0" />
      <geometry>
        <mesh filename="../../meshes/l_r_bar.STL" />
      </geometry>
    </collision> -->
  </link>
  <joint name="l_r_bar_y" type="continuous">
    <origin rpy="0 0 0" xyz="0 -0.0362 -0.153"/>
    <parent link="leg_l4_link"/>
    <child link="l_r_bar_y"/>
    <axis xyz="0 1 0"/>
  </joint>
  <link name="l_r_tendon_y">
    <inertial>
      <origin rpy="0 0 0" xyz="-1.9777E-05 0.00047927 -0.10625"/>
      <mass value="0.10643"/>
      <inertia ixx="0.0001972" ixy="4.1988E-12" ixz="-1.2811E-08" iyy="0.00019587" iyz="1.7341E-07" izz="3.9152E-06"/>
    </inertial>
    <visual>
      <origin rpy="0 0 0" xyz="0 0 0"/>
      <geometry>
        <mesh filename="../../meshes/l_r_tendon.STL"/>
      </geometry>
      <material name="">
        <color rgba="0.6902 0.65882 0.63922 1"/>
      </material>
    </visual>
    <!-- <collision>
      <origin xyz="0 0 0" rpy="0 0 0" />
      <geometry>
        <mesh filename="../../meshes/l_r_tendon.STL" />
      </geometry>
    </collision> -->
  </link>
  <drake:joint name="l_r_tendon_y" type="universal">
    <origin rpy="0 0 0" xyz="-0.056027 0.0085 0.015"/>
    <parent link="l_r_bar_y"/>
    <child link="l_r_tendon_y"/>
  </drake:joint>
  <frame link="l_r_tendon_y" name="l_r_tendon_socket" xyz="0 0 -0.193"/>
  <transmission type="SimpleTransmission">
    <joint name="l_r_bar_y"/>
    <actuator name="l_r_bar_y_motor">
      <drake:gear_ratio value="10.0"/>
      <drake:rotor_inertia value="0.0001002"/>
    </actuator>
  </transmission>
  <frame link="leg_l6_link" name="l_l_foot_socket" xyz="-0.056027 0.0255 0.015"/>
  <frame link="leg_l6_link" name="l_r_foot_socket" xyz="-0.056027 -0.0255 0.015"/>
  <!-- 曲柄 -->
  <frame link="l_l_bar_y" name="l_l_foot_bar_frame" xyz="0 -0.0085 0"/>
  <frame link="l_r_bar_y" name="l_r_foot_bar_frame" xyz="0 0.0085 0"/>
  <link name="leg_r1_link">
    <inertial>
      <origin xyz="-0.00540553 0.0 -0.0036909" rpy="0 0 0" />
      <mass value="1.79455971" />
      <inertia ixx="0.00210976" ixy="-1e-06" ixz="0.0001804" iyy="0.00298913" iyz="8e-08" izz="0.00395154" />
    </inertial>
    <visual>
      <origin xyz="0 0 0" rpy="0 0 0" />
      <geometry>
        <mesh filename="../../meshes/r_leg_roll.STL" />
      </geometry>
      <material name="">
        <color rgba="1 1 1 1" />
      </material>
    </visual>
  </link>
  <joint name="leg_r1_joint" type="revolute">
    <origin xyz="-0.0025 -0.087 -0.066" rpy="0 0 0" />
    <parent link="torso" />
    <child link="leg_r1_link" />
    <axis xyz="1 0 0" />
    <limit lower="-0.663225115757845" upper="0.314159265358979" effort="180.0" velocity="23.55" />
  </joint>
  <transmission type="SimpleTransmission">
    <joint name="leg_r1_joint" />
    <actuator name="leg_r1_joint_motor" />
  </transmission>
  <link name="leg_r2_link">
    <inertial>
      <origin xyz="-0.00598534 -0.01780742 -0.07118019" rpy="0 0 0" />
      <mass value="0.44959459" />
      <inertia ixx="0.00182949" ixy="-6.28e-06" ixz="-3.389e-05" iyy="0.00079345" iyz="-7.485e-05" izz="0.00142993" />
    </inertial>
    <visual>
      <origin xyz="0 0 0" rpy="0 0 0" />
      <geometry>
        <mesh filename="../../meshes/r_leg_yaw.STL" />
      </geometry>
      <material name="">
        <color rgba="1 1 1 1" />
      </material>
    </visual>
  </link>
  <joint name="leg_r2_joint" type="revolute">
    <origin xyz="0 0 0" rpy="0 0 0" />
    <parent link="leg_r1_link" />
    <child link="leg_r2_link" />
    <axis xyz="0 0 1" />
    <limit lower="-0.523598775598299" upper="1.0471975511966" effort="100.0" velocity="41.3433333333333" />
  </joint>
  <transmission type="SimpleTransmission">
    <joint name="leg_r2_joint" />
    <actuator name="leg_r2_joint_motor" />
  </transmission>
  <link name="leg_r3_link">
    <inertial>
      <origin xyz="-0.00145341 -0.00270854 -0.1012964" rpy="0 0 0" />
      <mass value="6.69346673" />
      <inertia ixx="0.09125521" ixy="-0.00044299" ixz="0.00298197" iyy="0.09331878" iyz="0.00019512" izz="0.01705978" />
    </inertial>
    <visual>
      <origin xyz="0 0 0" rpy="0 0 0" />
      <geometry>
        <mesh filename="../../meshes/r_leg_pitch.STL" />
      </geometry>
      <material name="">
        <color rgba="1 1 1 1" />
      </material>
    </visual>
  </link>
  <joint name="leg_r3_joint" type="revolute">
    <origin xyz="0 0 -0.125000000000001" rpy="0 0 0" />
    <parent link="leg_r2_link" />
    <child link="leg_r3_link" />
    <axis xyz="0 1 0" />
    <limit lower="-1.83259571459405" upper="1.0471975511966" effort="100.0" velocity="41.3433333333333" />
  </joint>
  <transmission type="SimpleTransmission">
    <joint name="leg_r3_joint" />
    <actuator name="leg_r3_joint_motor" />
  </transmission>
  <link name="leg_r4_link">
    <inertial>
      <origin xyz="-0.00940516 0.00022516 -0.15658596" rpy="0 0 0" />
      <mass value="2.2943738" />
      <inertia ixx="0.03342253" ixy="1.628e-05" ixz="-0.00306911" iyy="0.03408613" iyz="0.00021281" izz="0.00201392" />
    </inertial>
    <visual>
      <origin xyz="0 0 0" rpy="0 0 0" />
      <geometry>
        <mesh filename="../../meshes/r_knee.STL" />
      </geometry>
      <material name="">
        <color rgba="1 1 1 1" />
      </material>
    </visual>
  </link>
  <joint name="leg_r4_joint" type="revolute">
    <origin xyz="0.0419999999999999 0 -0.371446748811989" rpy="0 0 0" />
    <parent link="leg_r3_link" />
    <child link="leg_r4_link" />
    <axis xyz="0 1 0" />
    <limit lower="0.0" upper="2.00712863979348" effort="180.0" velocity="23.55" />
  </joint>
  <transmission type="SimpleTransmission">
    <joint name="leg_r4_joint" />
    <actuator name="leg_r4_joint_motor" />
  </transmission>
  <link name="leg_r5_link">
    <inertial>
      <origin xyz="0.0 0.0 0.0" rpy="0 0 0" />
      <mass value="0.07193524" />
      <inertia ixx="6.92e-06" ixy="0.0" ixz="0.0" iyy="6.92e-06" iyz="0.0" izz="1.218e-05" />
    </inertial>
    <visual>
      <origin xyz="0 0 0" rpy="0 0 0" />
      <geometry>
        <mesh filename="../../meshes/r_foot_pitch.STL" />
      </geometry>
      <material name="">
        <color rgba="1 1 1 1" />
      </material>
    </visual>
  </link>
  <joint name="leg_r5_joint" type="revolute">
    <origin xyz="0 0 -0.445999999999999" rpy="0 0 0" />
    <parent link="leg_r4_link" />
    <child link="leg_r5_link" />
    <axis xyz="0 1 0" />
    <limit lower="-0.567232006898157" upper="0.375245789178781" effort="36.0" velocity="23.0266666666667" />
  </joint>
  <transmission type="SimpleTransmission">
    <joint name="leg_r5_joint" />
    <actuator name="leg_r5_joint_motor" />
  </transmission>
  <link name="leg_r6_link">
    <inertial>
      <origin xyz="-0.01296272 7.7e-06 -0.03295687" rpy="0 0 0" />
      <mass value="0.57440357" />
      <inertia ixx="0.00069712" ixy="-1.4e-07" ixz="0.00046334" iyy="0.00226807" iyz="3e-08" izz="0.00232585" />
    </inertial>
    <visual>
      <origin xyz="0 0 0" rpy="0 0 0" />
      <geometry>
        <mesh filename="../../meshes/r_foot_roll.STL" />
      </geometry>
      <material name="">
        <color rgba="1 1 1 1" />
      </material>
    </visual>
  </link>
  <joint name="leg_r6_joint" type="revolute">
    <origin xyz="0 0 0" rpy="0 0 0" />
    <parent link="leg_r5_link" />
    <child link="leg_r6_link" />
    <axis xyz="1 0 0" />
    <limit lower="-0.349065850398866" upper="0.349065850398866" effort="36.0" velocity="23.0266666666667" />
  </joint>
  <transmission type="SimpleTransmission">
    <joint name="leg_r6_joint" />
    <actuator name="leg_r6_joint_motor" />
  </transmission>
  <!--        ssss -->
  <!-- sssssssss -->
  <link name="r_r_bar_y">
    <inertial>
      <origin rpy="0 0 0" xyz="-0.0176387949701166 0.0012332409395871 0.00472242692632874"/>
      <mass value="0.0413794520732275"/>
      <inertia ixx="6.34865185942549E-06" ixy="2.71679945417066E-06" ixz="4.93236590933488E-06" iyy="2.83792003165434E-05" iyz="-7.27368169902599E-07" izz="2.34510462869433E-05"/>
    </inertial>
    <visual>
      <origin rpy="0 0 0" xyz="0 0 0"/>
      <geometry>
        <mesh filename="../../meshes/r_r_bar.STL"/>
      </geometry>
      <material name="">
        <color rgba="0.690196078431373 0.658823529411765 0.63921568627451 1"/>
      </material>
    </visual>
    <!-- <collision>
      <origin xyz="0 0 0" rpy="0 0 0" />
      <geometry>
        <mesh filename="../../meshes/r_r_bar.STL" />
      </geometry>
    </collision> -->
  </link>
  <joint name="r_r_bar_y" type="continuous">
    <origin rpy="0 0 0" xyz="0 -0.0318 -0.09"/>
    <parent link="leg_r4_link"/>
    <child link="r_r_bar_y"/>
    <axis xyz="0 1 0"/>
  </joint>
  <link name="r_r_tendon_y">
    <inertial>
      <origin rpy="0 0 0" xyz="-1.36421989666846E-05 0.000483312127349173 -0.139530966436641"/>
      <mass value="0.132228698944171"/>
      <inertia ixx="0.000491608612358556" ixy="-3.05402199174078E-12" ixz="1.51985653969833E-08" iyy="0.000489725321370326" iyz="2.42627969905164E-07" izz="4.77496090027913E-06"/>
    </inertial>
    <visual>
      <origin rpy="0 0 0" xyz="0 0 0"/>
      <geometry>
        <mesh filename="../../meshes/r_r_tendon.STL"/>
      </geometry>
      <material name="">
        <color rgba="0.690196078431373 0.658823529411765 0.63921568627451 1"/>
      </material>
    </visual>
    <!-- <collision>
      <origin xyz="0 0 0" rpy="0 0 0" />
      <geometry>
        <mesh filename="../../meshes/r_r_tendon.STL" />
      </geometry>
    </collision> -->
  </link>
  <drake:joint name="r_r_tendon_y" type="universal">
    <origin rpy="0 0 0" xyz="-0.056027 0.0085 0.015"/>
    <parent link="r_r_bar_y"/>
    <child link="r_r_tendon_y"/>
  </drake:joint>
  <frame link="r_r_tendon_y" name="r_r_tendon_socket" xyz="0 0 -0.256"/>
  <transmission type="SimpleTransmission">
    <joint name="r_r_bar_y"/>
    <actuator name="r_r_bar_y_motor">
      <drake:gear_ratio value="10.0"/>
      <drake:rotor_inertia value="0.0001002"/>
    </actuator>
  </transmission>
  <link name="r_l_bar_y">
    <inertial>
      <origin rpy="0 0 0" xyz="-0.0176387868876003 -0.00123323826800568 0.00472240978820238"/>
      <mass value="0.0413794348706216"/>
      <inertia ixx="6.34864114001538E-06" ixy="-2.71679701707313E-06" ixz="4.93234664344148E-06" iyy="2.83791841625158E-05" iyz="7.2736352651351E-07" izz="2.34510398457472E-05"/>
    </inertial>
    <visual>
      <origin rpy="0 0 0" xyz="0 0 0"/>
      <geometry>
        <mesh filename="../../meshes/r_l_bar.STL"/>
      </geometry>
      <material name="">
        <color rgba="0.690196078431373 0.658823529411765 0.63921568627451 1"/>
      </material>
    </visual>
    <!-- <collision>
      <origin xyz="0 0 0" rpy="0 0 0" />
      <geometry>
        <mesh filename="../../meshes/r_l_bar.STL" />
      </geometry>
    </collision> -->
  </link>
  <joint name="r_l_bar_y" type="continuous">
    <origin rpy="0 0 0" xyz="0 0.0362 -0.153"/>
    <parent link="leg_r4_link"/>
    <child link="r_l_bar_y"/>
    <axis xyz="0 1 0"/>
  </joint>
  <transmission type="SimpleTransmission">
    <joint name="r_l_bar_y"/>
    <actuator name="r_l_bar_y_motor">
      <drake:gear_ratio value="10.0"/>
      <drake:rotor_inertia value="0.0001002"/>
    </actuator>
  </transmission>
  <link name="r_l_tendon_y">
    <inertial>
      <origin rpy="0 0 0" xyz="-1.97765085516513E-05 -0.00047926628765782 -0.106248164342492"/>
      <mass value="0.106425376742002"/>
      <inertia ixx="0.000197199480044112" ixy="-4.20204697681874E-12" ixz="-1.28105270857608E-08" iyy="0.00019587468108075" iyz="-1.73407864727289E-07" izz="3.91523487668242E-06"/>
    </inertial>
    <visual>
      <origin rpy="0 0 0" xyz="0 0 0"/>
      <geometry>
        <mesh filename="../../meshes/r_l_tendon.STL"/>
      </geometry>
      <material name="">
        <color rgba="0.690196078431373 0.658823529411765 0.63921568627451 1"/>
      </material>
    </visual>
    <!-- <collision>
      <origin xyz="0 0 0" rpy="0 0 0" />
      <geometry>
        <mesh filename="../../meshes/r_l_tendon.STL" />
      </geometry>
    </collision> -->
  </link>
  <drake:joint name="r_l_tendon_y" type="universal">
    <origin rpy="0 0 0" xyz="-0.056027 -0.0085 0.015"/>
    <parent link="r_l_bar_y"/>
    <child link="r_l_tendon_y"/>
  </drake:joint>
  <frame link="r_l_tendon_y" name="r_l_tendon_socket" xyz="0 0 -0.193"/>
  <frame link="leg_r6_link" name="r_l_foot_socket" xyz="-0.056027 0.0255 0.015"/>
  <frame link="leg_r6_link" name="r_r_foot_socket" xyz="-0.056027 -0.0255 0.015"/>
  <!-- 曲柄 -->
  <frame link="r_l_bar_y" name="r_l_foot_bar_frame" xyz="0 -0.0085 0"/>
  <frame link="r_r_bar_y" name="r_r_foot_bar_frame" xyz="0 0.0085 0"/>
  <!-- =========================================================== Arms ================================================================= -->
  <link name="zarm_l1_link">
    <inertial>
      <origin xyz="0.008 -0.00158 0.0036" rpy="0 0 0" />
      <mass value="1.15" />
      <inertia ixx="0.0006" ixy="5e-05" ixz="1e-05" iyy="0.00048" iyz="-6e-05" izz="0.0007" />
    </inertial>
    <visual>
      <origin xyz="0 0 0" rpy="0 0 0" />
      <geometry>
        <mesh filename="../../meshes/l_arm_pitch.STL" />
      </geometry>
      <material name="">
        <color rgba="1 1 1 1" />
      </material>
    </visual>
  </link>
  <joint name="zarm_l1_joint" type="revolute">
    <origin xyz="-0.0175 0.25886 0.3245" rpy="0 0 0" />
    <parent link="torso" />
    <child link="zarm_l1_link" />
    <axis xyz="0 1 0" />
    <limit lower="-2.61799387799149" upper="0.523598775598299" effort="100.0" velocity="41.3433333333333" />
  </joint>
  <transmission type="SimpleTransmission">
    <joint name="zarm_l1_joint" />
    <actuator name="zarm_l1_joint_motor" />
  </transmission>
  <link name="zarm_l2_link">
    <inertial>
      <origin xyz="0.00144 0.02159 -0.0202" rpy="0 0 0" />
      <mass value="0.226" />
      <inertia ixx="0.0003" ixy="3e-05" ixz="1e-05" iyy="0.00061" iyz="5e-05" izz="0.00057" />
    </inertial>
    <visual>
      <origin xyz="0 0 0" rpy="0 0 0" />
      <geometry>
        <mesh filename="../../meshes/l_arm_roll.STL" />
      </geometry>
      <material name="">
        <color rgba="1 1 1 1" />
      </material>
    </visual>
  </link>
  <joint name="zarm_l2_joint" type="revolute">
    <origin xyz="0 0 0" rpy="0 0 0" />
    <parent link="zarm_l1_link" />
    <child link="zarm_l2_link" />
    <axis xyz="1 0 0" />
    <limit lower="-0.349065850398866" upper="2.0943951023932" effort="50.0" velocity="19.154" />
  </joint>
  <transmission type="SimpleTransmission">
    <joint name="zarm_l2_joint" />
    <actuator name="zarm_l2_joint_motor" />
  </transmission>
  <link name="zarm_l3_link">
    <inertial>
      <origin xyz="-0.00157 -3e-05 -0.13318" rpy="0 0 0" />
      <mass value="1.166" />
      <inertia ixx="0.00245" ixy="-1e-05" ixz="-1e-05" iyy="0.0022" iyz="0.0" izz="0.00112" />
    </inertial>
    <visual>
      <origin xyz="0 0 0" rpy="0 0 0" />
      <geometry>
        <mesh filename="../../meshes/l_arm_yaw.STL" />
      </geometry>
      <material name="">
        <color rgba="1 1 1 1" />
      </material>
    </visual>
  </link>
  <joint name="zarm_l3_joint" type="revolute">
    <origin xyz="0 0 0" rpy="0 0 0" />
    <parent link="zarm_l2_link" />
    <child link="zarm_l3_link" />
    <axis xyz="0 0 1" />
    <limit lower="-1.5707963267949" upper="1.5707963267949" effort="20.0" velocity="18.84" />
  </joint>
  <transmission type="SimpleTransmission">
    <joint name="zarm_l3_joint" />
    <actuator name="zarm_l3_joint_motor" />
  </transmission>
  <link name="zarm_l4_link">
    <inertial>
      <origin xyz="-4e-05 0.0098 -0.05283" rpy="0 0 0" />
      <mass value="0.575" />
      <inertia ixx="0.00098" ixy="0.0" ixz="0.0" iyy="0.00062" iyz="-0.00016" izz="0.00088" />
    </inertial>
    <visual>
      <origin xyz="0 0 0" rpy="0 0 0" />
      <geometry>
        <mesh filename="../../meshes/l_forearm.STL" />
      </geometry>
      <material name="">
        <color rgba="1 1 1 1" />
      </material>
    </visual>
  </link>
  <joint name="zarm_l4_joint" type="revolute">
    <origin xyz="0 0 -0.1646" rpy="0 0 0" />
    <parent link="zarm_l3_link" />
    <child link="zarm_l4_link" />
    <axis xyz="0 1 0" />
    <limit lower="-1.5707963267949" upper="0.0" effort="20.0" velocity="18.84" />
  </joint>
  <transmission type="SimpleTransmission">
    <joint name="zarm_l4_joint" />
    <actuator name="zarm_l4_joint_motor" />
  </transmission>
  <link name="zarm_l5_link">
    <inertial>
      <origin xyz="-0.00011 0.00421 -0.11168" rpy="0 0 0" />
      <mass value="0.46" />
      <inertia ixx="0.00077" ixy="0.0" ixz="0.0" iyy="0.0005" iyz="-4e-05" izz="0.00063" />
    </inertial>
    <visual>
      <origin xyz="0 0 0" rpy="0 0 0" />
      <geometry>
        <mesh filename="../../meshes/l_hand_yaw.STL" />
      </geometry>
      <material name="">
        <color rgba="1 1 1 1" />
      </material>
    </visual>
  </link>
  <joint name="zarm_l5_joint" type="revolute">
    <origin xyz="0 0 0" rpy="0 0 0" />
    <parent link="zarm_l4_link" />
    <child link="zarm_l5_link" />
    <axis xyz="0 0 1" />
    <limit lower="-1.5707963267949" upper="1.5707963267949" effort="6.0" velocity="21.666" />
  </joint>
  <transmission type="SimpleTransmission">
    <joint name="zarm_l5_joint" />
    <actuator name="zarm_l5_joint_motor" />
  </transmission>
  <link name="zarm_l6_link">
    <inertial>
      <origin xyz="0.00253 0.00382 -0.05356" rpy="0 0 0" />
      <mass value="0.35" />
      <inertia ixx="0.00023" ixy="0.0" ixz="0.0" iyy="0.00024" iyz="-4e-05" izz="0.00019" />
    </inertial>
    <visual>
      <origin xyz="0 0 0" rpy="0 0 0" />
      <geometry>
        <mesh filename="../../meshes/l_hand_pitch.STL" />
      </geometry>
      <material name="">
        <color rgba="1 1 1 1" />
      </material>
    </visual>
  </link>
  <joint name="zarm_l6_joint" type="revolute">
    <origin xyz="0 0 -0.132050000125748" rpy="0 0 0" />
    <parent link="zarm_l5_link" />
    <child link="zarm_l6_link" />
    <axis xyz="0 1 0" />
    <limit lower="-1.5707963267949" upper="1.5707963267949" effort="6.0" velocity="21.666" />
  </joint>
  <transmission type="SimpleTransmission">
    <joint name="zarm_l6_joint" />
    <actuator name="zarm_l6_joint_motor" />
  </transmission>
  <link name="zarm_l7_link">
    <inertial>
      <origin xyz="0.00267 0.00748 -0.07162" rpy="0 0 0" />
      <mass value="0.81" />
      <inertia ixx="0.00117" ixy="2e-05" ixz="0.0" iyy="0.00128" iyz="-2e-05" izz="0.00036" />
    </inertial>
    <visual>
      <origin xyz="0 0 0" rpy="0 0 0" />
      <geometry>
        <mesh filename="../../meshes/l_hand_roll.STL" />
      </geometry>
      <material name="">
        <color rgba="1 1 1 1" />
      </material>
    </visual>
  </link>
  <joint name="zarm_l7_joint" type="revolute">
    <origin xyz="0 0 -0.0589999999999999" rpy="0 0 0" />
    <parent link="zarm_l6_link" />
    <child link="zarm_l7_link" />
    <axis xyz="1 0 0" />
    <limit lower="-1.5707963267949" upper="1.5707963267949" effort="6.0" velocity="21.666" />
  </joint>
  <transmission type="SimpleTransmission">
    <joint name="zarm_l7_joint" />
    <actuator name="zarm_l7_joint_motor" />
  </transmission>
  <link name="zarm_r1_link">
    <inertial>
      <origin xyz="0.008 0.00158 -0.0036" rpy="0 0 0" />
      <mass value="1.15" />
      <inertia ixx="0.0006" ixy="-5e-05" ixz="-1e-05" iyy="0.00048" iyz="-6e-05" izz="0.0007" />
    </inertial>
    <visual>
      <origin xyz="0 0 0" rpy="0 0 0" />
      <geometry>
        <mesh filename="../../meshes/r_arm_pitch.STL" />
      </geometry>
      <material name="">
        <color rgba="1 1 1 1" />
      </material>
    </visual>
  </link>
  <joint name="zarm_r1_joint" type="revolute">
    <origin xyz="-0.0175 -0.25886 0.3245" rpy="0 0 0" />
    <parent link="torso" />
    <child link="zarm_r1_link" />
    <axis xyz="0 1 0" />
    <limit lower="-2.61799387799149" upper="0.523598775598299" effort="100.0" velocity="41.3433333333333" />
  </joint>
  <transmission type="SimpleTransmission">
    <joint name="zarm_r1_joint" />
    <actuator name="zarm_r1_joint_motor" />
  </transmission>
  <link name="zarm_r2_link">
    <inertial>
      <origin xyz="0.00144 -0.02159 -0.02021" rpy="0 0 0" />
      <mass value="0.226" />
      <inertia ixx="0.0003" ixy="-3e-05" ixz="1e-05" iyy="0.00061" iyz="-5e-05" izz="0.00057" />
    </inertial>
    <visual>
      <origin xyz="0 0 0" rpy="0 0 0" />
      <geometry>
        <mesh filename="../../meshes/r_arm_roll.STL" />
      </geometry>
      <material name="">
        <color rgba="1 1 1 1" />
      </material>
    </visual>
  </link>
  <joint name="zarm_r2_joint" type="revolute">
    <origin xyz="0 0 0" rpy="0 0 0" />
    <parent link="zarm_r1_link" />
    <child link="zarm_r2_link" />
    <axis xyz="1 0 0" />
    <limit lower="-2.0943951023932" upper="0.349065850398866" effort="50.0" velocity="19.154" />
  </joint>
  <transmission type="SimpleTransmission">
    <joint name="zarm_r2_joint" />
    <actuator name="zarm_r2_joint_motor" />
  </transmission>
  <link name="zarm_r3_link">
    <inertial>
      <origin xyz="-0.00157 3e-05 -0.13318" rpy="0 0 0" />
      <mass value="1.166" />
      <inertia ixx="0.00245" ixy="1e-05" ixz="-1e-05" iyy="0.0022" iyz="0.0" izz="0.00112" />
    </inertial>
    <visual>
      <origin xyz="0 0 0" rpy="0 0 0" />
      <geometry>
        <mesh filename="../../meshes/r_arm_yaw.STL" />
      </geometry>
      <material name="">
        <color rgba="1 1 1 1" />
      </material>
    </visual>
  </link>
  <joint name="zarm_r3_joint" type="revolute">
    <origin xyz="0 0 0" rpy="0 0 0" />
    <parent link="zarm_r2_link" />
    <child link="zarm_r3_link" />
    <axis xyz="0 0 1" />
    <limit lower="-1.5707963267949" upper="1.5707963267949" effort="20.0" velocity="18.84" />
  </joint>
  <transmission type="SimpleTransmission">
    <joint name="zarm_r3_joint" />
    <actuator name="zarm_r3_joint_motor" />
  </transmission>
  <link name="zarm_r4_link">
    <inertial>
      <origin xyz="-4e-05 -0.0098 -0.05283" rpy="0 0 0" />
      <mass value="0.575" />
      <inertia ixx="0.00098" ixy="0.0" ixz="0.0" iyy="0.00062" iyz="0.00016" izz="0.00088" />
    </inertial>
    <visual>
      <origin xyz="0 0 0" rpy="0 0 0" />
      <geometry>
        <mesh filename="../../meshes/r_forearm.STL" />
      </geometry>
      <material name="">
        <color rgba="1 1 1 1" />
      </material>
    </visual>
  </link>
  <joint name="zarm_r4_joint" type="revolute">
    <origin xyz="0 0 -0.1646" rpy="0 0 0" />
    <parent link="zarm_r3_link" />
    <child link="zarm_r4_link" />
    <axis xyz="0 1 0" />
    <limit lower="-1.5707963267949" upper="0.0" effort="20.0" velocity="18.84" />
  </joint>
  <transmission type="SimpleTransmission">
    <joint name="zarm_r4_joint" />
    <actuator name="zarm_r4_joint_motor" />
  </transmission>
  <link name="zarm_r5_link">
    <inertial>
      <origin xyz="-0.00011 -0.00421 -0.11168" rpy="0 0 0" />
      <mass value="0.46" />
      <inertia ixx="0.00077" ixy="0.0" ixz="0.0" iyy="0.0005" iyz="4e-05" izz="0.00063" />
    </inertial>
    <visual>
      <origin xyz="0 0 0" rpy="0 0 0" />
      <geometry>
        <mesh filename="../../meshes/r_hand_yaw.STL" />
      </geometry>
      <material name="">
        <color rgba="1 1 1 1" />
      </material>
    </visual>
  </link>
  <joint name="zarm_r5_joint" type="revolute">
    <origin xyz="0 0 0" rpy="0 0 0" />
    <parent link="zarm_r4_link" />
    <child link="zarm_r5_link" />
    <axis xyz="0 0 1" />
    <limit lower="-1.5707963267949" upper="1.5707963267949" effort="6.0" velocity="21.666" />
  </joint>
  <transmission type="SimpleTransmission">
    <joint name="zarm_r5_joint" />
    <actuator name="zarm_r5_joint_motor" />
  </transmission>
  <link name="zarm_r6_link">
    <inertial>
      <origin xyz="0.00253 -0.00382 -0.05356" rpy="0 0 0" />
      <mass value="0.35" />
      <inertia ixx="0.00023" ixy="0.0" ixz="0.0" iyy="0.00024" iyz="4e-05" izz="0.00019" />
    </inertial>
    <visual>
      <origin xyz="0 0 0" rpy="0 0 0" />
      <geometry>
        <mesh filename="../../meshes/r_hand_pitch.STL" />
      </geometry>
      <material name="">
        <color rgba="1 1 1 1" />
      </material>
    </visual>
  </link>
  <joint name="zarm_r6_joint" type="revolute">
    <origin xyz="0 0 -0.132050000240097" rpy="0 0 0" />
    <parent link="zarm_r5_link" />
    <child link="zarm_r6_link" />
    <axis xyz="0 1 0" />
    <limit lower="-1.5707963267949" upper="1.5707963267949" effort="6.0" velocity="21.666" />
  </joint>
  <transmission type="SimpleTransmission">
    <joint name="zarm_r6_joint" />
    <actuator name="zarm_r6_joint_motor" />
  </transmission>
  <link name="zarm_r7_link">
    <inertial>
      <origin xyz="0.00267 -0.00748 -0.07162" rpy="0 0 0" />
      <mass value="0.81" />
      <inertia ixx="0.00098" ixy="-1e-05" ixz="1e-05" iyy="0.00104" iyz="1e-05" izz="0.00027" />
    </inertial>
    <visual>
      <origin xyz="0 0 0" rpy="0 0 0" />
      <geometry>
        <mesh filename="../../meshes/r_hand_roll.STL" />
      </geometry>
      <material name="">
        <color rgba="1 1 1 1" />
      </material>
    </visual>
  </link>
  <joint name="zarm_r7_joint" type="revolute">
    <origin xyz="0 0 -0.0589999999999999" rpy="0 0 0" />
    <parent link="zarm_r6_link" />
    <child link="zarm_r7_link" />
    <axis xyz="1 0 0" />
    <limit lower="-1.5707963267949" upper="1.5707963267949" effort="6.0" velocity="21.666" />
  </joint>
  <transmission type="SimpleTransmission">
    <joint name="zarm_r7_joint" />
    <actuator name="zarm_r7_joint_motor" />
  </transmission>
  <!-- end frame -->
  <!-- <frame link="l_hand_pitch" name="l_hand_sole" xyz="0 0 -0.1" /> -->
  <!-- end frame -->
  <!-- <frame link="r_hand_pitch" name="r_hand_sole" xyz="0 0 -0.1" /> -->
</robot>

