<?xml version='1.0' encoding='utf-8'?>
<robot name="biped_s50">
  <mujoco>
    <compiler meshdir="../meshes/" balanceinertia="true" discardvisual="false" />
  </mujoco>
  <link name="dummy_link" />
  <link name="base_link">
    <inertial>
      <origin xyz="-0.00505 0.0014 0.18077" rpy="0 0 0" />
      <mass value="21.0" />
      <inertia ixx="0.28214" ixy="3e-05" ixz="0.01114" iyy="0.20534" iyz="0.00044" izz="0.13735" />
    </inertial>
    <visual>
      <origin xyz="0 0 0" rpy="0 0 0" />
      <geometry>
        <mesh filename="package://kuavo_assets/models/biped_s50/meshes/base_link.STL" />
      </geometry>
      <material name="">
        <color rgba="1 1 1 1" />
      </material>
    </visual>
    <collision>
      <origin
        xyz="-0.02 0 0.22" rpy="0 0 0" />
      <geometry>
        <box size="0.23 0.33 0.42" />
      </geometry>
    </collision>
  </link>
  <joint name="dummy_to_base_link" type="floating">
    <origin xyz="0 0 0" rpy="0 0 0" />
    <parent link="dummy_link" />
    <child link="base_link" />
  </joint>
  <link name="leg_l1_link">
    <inertial>
      <origin xyz="-0.00540552 0.0 -0.00369091" rpy="0 0 0" />
      <mass value="1.79455987" />
      <inertia ixx="0.00210976" ixy="1e-06" ixz="0.0001804" iyy="0.00298913" iyz="-8e-08" izz="0.00395154" />
    </inertial>
    <visual>
      <origin xyz="0 0 0" rpy="0 0 0" />
      <geometry>
        <mesh filename="package://kuavo_assets/models/biped_s50/meshes/l_leg_roll.STL" />
      </geometry>
      <material name="">
        <color rgba="1 1 1 1" />
      </material>
    </visual>
  </link>
  <joint name="leg_l1_joint" type="revolute">
    <origin xyz="-0.0025 0.087 -0.066" rpy="0 0 0" />
    <parent link="base_link" />
    <child link="leg_l1_link" />
    <axis xyz="1 0 0" />
    <limit lower="-0.314159265358979" upper="0.663225115757845" effort="180.0" velocity="23.55" />
  </joint>
  <link name="leg_l2_link">
    <inertial>
      <origin xyz="-0.0059853 0.01780742 -0.0711802" rpy="0 0 0" />
      <mass value="0.44959459" />
      <inertia ixx="0.00182951" ixy="6.31e-06" ixz="-3.379e-05" iyy="0.00079345" iyz="7.485e-05" izz="0.00142992" />
    </inertial>
    <visual>
      <origin xyz="0 0 0" rpy="0 0 0" />
      <geometry>
        <mesh filename="package://kuavo_assets/models/biped_s50/meshes/l_leg_yaw.STL" />
      </geometry>
      <material name="">
        <color rgba="1 1 1 1" />
      </material>
    </visual>
  </link>
  <joint name="leg_l2_joint" type="revolute">
    <origin xyz="0 0 0" rpy="0 0 0" />
    <parent link="leg_l1_link" />
    <child link="leg_l2_link" />
    <axis xyz="0 0 1" />
    <limit lower="-1.0471975511966" upper="0.523598775598299" effort="100.0" velocity="41.3433333333333" />
  </joint>
  <link name="leg_l3_link">
    <inertial>
      <origin xyz="-0.00144817 0.00270737 -0.10124151" rpy="0 0 0" />
      <mass value="6.69326562" />
      <inertia ixx="0.09123938" ixy="0.00044201" ixz="0.0029849" iyy="0.09330391" iyz="-0.00021264" izz="0.01705855" />
    </inertial>
    <visual>
      <origin xyz="0 0 0" rpy="0 0 0" />
      <geometry>
        <mesh filename="package://kuavo_assets/models/biped_s50/meshes/l_leg_pitch.STL" />
      </geometry>
      <material name="">
        <color rgba="1 1 1 1" />
      </material>
    </visual>
    <collision>
      <origin xyz="0.01 0.0 -0.125" rpy="0.0 -0.1 0.0"/>
      <geometry>
        <cylinder radius="0.065" length="0.35"/>
      </geometry>
    </collision>
  </link>
  <joint name="leg_l3_joint" type="revolute">
    <origin xyz="0 0 -0.124999999999996" rpy="0 0 0" />
    <parent link="leg_l2_link" />
    <child link="leg_l3_link" />
    <axis xyz="0 1 0" />
    <limit lower="-1.83259571459405" upper="1.0471975511966" effort="100.0" velocity="41.3433333333333" />
  </joint>
  <link name="leg_l4_link">
    <inertial>
      <origin xyz="-0.00940804 -0.00020026 -0.1566321" rpy="0 0 0" />
      <mass value="2.29375237" />
      <inertia ixx="0.03340685" ixy="-1.739e-05" ixz="-0.00306822" iyy="0.03407041" iyz="-0.00021711" izz="0.00201364" />
    </inertial>
    <visual>
      <origin xyz="0 0 0" rpy="0 0 0" />
      <geometry>
        <mesh filename="package://kuavo_assets/models/biped_s50/meshes/l_knee.STL" />
      </geometry>
      <material name="">
        <color rgba="1 1 1 1" />
      </material>
    </visual>
    <collision>
      <origin xyz="0.0 0.0 -0.2" rpy="0.0 0.0 0.0"/>
      <geometry>
        <cylinder radius="0.04" length="0.3"/>
      </geometry>
    </collision>
  </link>
  <joint name="leg_l4_joint" type="revolute">
    <origin xyz="0.0419999999999991 0 -0.371446748811991" rpy="0 0 0" />
    <parent link="leg_l3_link" />
    <child link="leg_l4_link" />
    <axis xyz="0 1 0" />
    <limit lower="0.0" upper="2.00712863979348" effort="180.0" velocity="23.55" />
  </joint>
  <link name="leg_l5_link">
    <inertial>
      <origin xyz="0.0 0.0 0.0" rpy="0 0 0" />
      <mass value="0.07193524" />
      <inertia ixx="6.92e-06" ixy="0.0" ixz="0.0" iyy="6.92e-06" iyz="0.0" izz="1.218e-05" />
    </inertial>
    <visual>
      <origin xyz="0 0 0" rpy="0 0 0" />
      <geometry>
        <mesh filename="package://kuavo_assets/models/biped_s50/meshes/l_foot_pitch.STL" />
      </geometry>
      <material name="">
        <color rgba="1 1 1 1" />
      </material>
    </visual>
  </link>
  <joint name="leg_l5_joint" type="revolute">
    <origin xyz="0 0 -0.446000000000003" rpy="0 0 0" />
    <parent link="leg_l4_link" />
    <child link="leg_l5_link" />
    <axis xyz="0 1 0" />
    <limit lower="-0.567232006898157" upper="0.375245789178781" effort="36.0" velocity="23.0266666666667" />
  </joint>
  <link name="leg_l6_link">
    <inertial>
      <origin xyz="-0.0129597 -7.73e-06 -0.03296708" rpy="0 0 0" />
      <mass value="0.57421229" />
      <inertia ixx="0.00069693" ixy="1.4e-07" ixz="0.00046328" iyy="0.00226786" iyz="-3e-08" izz="0.00232583" />
    </inertial>
    <visual>
      <origin xyz="0 0 0" rpy="0 0 0" />
      <geometry>
        <mesh filename="package://kuavo_assets/models/biped_s50/meshes/l_foot_roll.STL" />
      </geometry>
      <material name="">
        <color rgba="1 1 1 1" />
      </material>
    </visual>
    <collision>
      <origin rpy="0 0 0" xyz="0.02 0 -0.055" />
      <geometry>
        <box size="0.25 0.1 0.01"/>
      </geometry>
    </collision>
  </link>
  <joint name="leg_l6_joint" type="revolute">
    <origin xyz="0 0 0" rpy="0 0 0" />
    <parent link="leg_l5_link" />
    <child link="leg_l6_link" />
    <axis xyz="1 0 0" />
    <limit lower="-0.349065850398866" upper="0.349065850398866" effort="36.0" velocity="23.0266666666667" />
  </joint>
  <link name="ll_foot_toe">
    <!-- <collision>
      <origin rpy="0 0 0" xyz="0 0 0" />
      <geometry>
        <sphere radius="0.005" />
      </geometry>
    </collision> -->
  </link>
  <joint name="ll_foot_toe_joint" type="fixed">
    <origin xyz="0.142507 0.04773 -0.0595" rpy="0 0 0" />
    <parent link="leg_l6_link" />
    <child link="ll_foot_toe" />
  </joint>
  <link name="ll_foot_heel">
    <!-- <collision>
      <origin rpy="0 0 0" xyz="0 0 0" />
      <geometry>
        <sphere radius="0.005" />
      </geometry>
    </collision> -->
  </link>
  <joint name="ll_foot_heel_joint" type="fixed">
    <origin xyz="-0.10149 0.04773 -0.0595" rpy="0 0 0" />
    <parent link="leg_l6_link" />
    <child link="ll_foot_heel" />
  </joint>
  <link name="lr_foot_toe">
    <!-- <collision>
      <origin rpy="0 0 0" xyz="0 0 0" />
      <geometry>
        <sphere radius="0.005" />
      </geometry>
    </collision> -->
  </link>
  <joint name="lr_foot_toe_joint" type="fixed">
    <origin xyz="0.142507 -0.04773 -0.0595" rpy="0 0 0" />
    <parent link="leg_l6_link" />
    <child link="lr_foot_toe" />
  </joint>
  <link name="lr_foot_heel">
    <!-- <collision>
      <origin rpy="0 0 0" xyz="0 0 0" />
      <geometry>
        <sphere radius="0.005" />
      </geometry>
    </collision> -->
  </link>
  <joint name="lr_foot_heel_joint" type="fixed">
    <origin xyz="-0.10149 -0.04773 -0.0595" rpy="0 0 0" />
    <parent link="leg_l6_link" />
    <child link="lr_foot_heel" />
  </joint>
  <link name="l_foot_toe">
    <!-- <collision>
      <origin rpy="0 0 0" xyz="0 0 0" />
      <geometry>
        <sphere radius="0.005" />
      </geometry>
    </collision> -->
  </link>
  <joint name="l_foot_toe_joint" type="fixed">
    <origin xyz="0.142507 0.0 -0.0595" rpy="0 0 0" />
    <parent link="leg_l6_link" />
    <child link="l_foot_toe" />
  </joint>
  <link name="l_foot_heel">
    <!-- <collision>
      <origin rpy="0 0 0" xyz="0 0 0" />
      <geometry>
        <sphere radius="0.005" />
      </geometry>
    </collision> -->
  </link>
  <joint name="l_foot_heel_joint" type="fixed">
    <origin xyz="-0.10149 0.0 -0.0595" rpy="0 0 0" />
    <parent link="leg_l6_link" />
    <child link="l_foot_heel" />
  </joint>
  <link name="leg_r1_link">
    <inertial>
      <origin xyz="-0.00540553 0.0 -0.0036909" rpy="0 0 0" />
      <mass value="1.79455971" />
      <inertia ixx="0.00210976" ixy="-1e-06" ixz="0.0001804" iyy="0.00298913" iyz="8e-08" izz="0.00395154" />
    </inertial>
    <visual>
      <origin xyz="0 0 0" rpy="0 0 0" />
      <geometry>
        <mesh filename="package://kuavo_assets/models/biped_s50/meshes/r_leg_roll.STL" />
      </geometry>
      <material name="">
        <color rgba="1 1 1 1" />
      </material>
    </visual>
  </link>
  <joint name="leg_r1_joint" type="revolute">
    <origin xyz="-0.0025 -0.087 -0.066" rpy="0 0 0" />
    <parent link="base_link" />
    <child link="leg_r1_link" />
    <axis xyz="1 0 0" />
    <limit lower="-0.663225115757845" upper="0.314159265358979" effort="180.0" velocity="23.55" />
  </joint>
  <link name="leg_r2_link">
    <inertial>
      <origin xyz="-0.00598534 -0.01780742 -0.07118019" rpy="0 0 0" />
      <mass value="0.44959459" />
      <inertia ixx="0.00182949" ixy="-6.28e-06" ixz="-3.389e-05" iyy="0.00079345" iyz="-7.485e-05" izz="0.00142993" />
    </inertial>
    <visual>
      <origin xyz="0 0 0" rpy="0 0 0" />
      <geometry>
        <mesh filename="package://kuavo_assets/models/biped_s50/meshes/r_leg_yaw.STL" />
      </geometry>
      <material name="">
        <color rgba="1 1 1 1" />
      </material>
    </visual>
  </link>
  <joint name="leg_r2_joint" type="revolute">
    <origin xyz="0 0 0" rpy="0 0 0" />
    <parent link="leg_r1_link" />
    <child link="leg_r2_link" />
    <axis xyz="0 0 1" />
    <limit lower="-0.523598775598299" upper="1.0471975511966" effort="100.0" velocity="41.3433333333333" />
  </joint>
  <link name="leg_r3_link">
    <inertial>
      <origin xyz="-0.00145341 -0.00270854 -0.1012964" rpy="0 0 0" />
      <mass value="6.69346673" />
      <inertia ixx="0.09125521" ixy="-0.00044299" ixz="0.00298197" iyy="0.09331878" iyz="0.00019512" izz="0.01705978" />
    </inertial>
    <visual>
      <origin xyz="0 0 0" rpy="0 0 0" />
      <geometry>
        <mesh filename="package://kuavo_assets/models/biped_s50/meshes/r_leg_pitch.STL" />
      </geometry>
      <material name="">
        <color rgba="1 1 1 1" />
      </material>
    </visual>
    <collision>
      <origin xyz="0.01 0.0 -0.125" rpy="0.0 -0.1 0.0"/>
      <geometry>
        <cylinder radius="0.065" length="0.35"/>
      </geometry>
    </collision>
  </link>
  <joint name="leg_r3_joint" type="revolute">
    <origin xyz="0 0 -0.125000000000001" rpy="0 0 0" />
    <parent link="leg_r2_link" />
    <child link="leg_r3_link" />
    <axis xyz="0 1 0" />
    <limit lower="-1.83259571459405" upper="1.0471975511966" effort="100.0" velocity="41.3433333333333" />
  </joint>
  <link name="leg_r4_link">
    <inertial>
      <origin xyz="-0.00940516 0.00022516 -0.15658596" rpy="0 0 0" />
      <mass value="2.2943738" />
      <inertia ixx="0.03342253" ixy="1.628e-05" ixz="-0.00306911" iyy="0.03408613" iyz="0.00021281" izz="0.00201392" />
    </inertial>
    <visual>
      <origin xyz="0 0 0" rpy="0 0 0" />
      <geometry>
        <mesh filename="package://kuavo_assets/models/biped_s50/meshes/r_knee.STL" />
      </geometry>
      <material name="">
        <color rgba="1 1 1 1" />
      </material>
    </visual>
    <collision>
      <origin xyz="0.0 0.0 -0.2" rpy="0.0 0.0 0.0"/>
      <geometry>
        <cylinder radius="0.04" length="0.3"/>
      </geometry>
    </collision>
  </link>
  <joint name="leg_r4_joint" type="revolute">
    <origin xyz="0.0419999999999999 0 -0.371446748811989" rpy="0 0 0" />
    <parent link="leg_r3_link" />
    <child link="leg_r4_link" />
    <axis xyz="0 1 0" />
    <limit lower="0.0" upper="2.00712863979348" effort="180.0" velocity="23.55" />
  </joint>
  <link name="leg_r5_link">
    <inertial>
      <origin xyz="0.0 0.0 0.0" rpy="0 0 0" />
      <mass value="0.07193524" />
      <inertia ixx="6.92e-06" ixy="0.0" ixz="0.0" iyy="6.92e-06" iyz="0.0" izz="1.218e-05" />
    </inertial>
    <visual>
      <origin xyz="0 0 0" rpy="0 0 0" />
      <geometry>
        <mesh filename="package://kuavo_assets/models/biped_s50/meshes/r_foot_pitch.STL" />
      </geometry>
      <material name="">
        <color rgba="1 1 1 1" />
      </material>
    </visual>
  </link>
  <joint name="leg_r5_joint" type="revolute">
    <origin xyz="0 0 -0.445999999999999" rpy="0 0 0" />
    <parent link="leg_r4_link" />
    <child link="leg_r5_link" />
    <axis xyz="0 1 0" />
    <limit lower="-0.567232006898157" upper="0.375245789178781" effort="36.0" velocity="23.0266666666667" />
  </joint>
  <link name="leg_r6_link">
    <inertial>
      <origin xyz="-0.01296272 7.7e-06 -0.03295687" rpy="0 0 0" />
      <mass value="0.57440357" />
      <inertia ixx="0.00069712" ixy="-1.4e-07" ixz="0.00046334" iyy="0.00226807" iyz="3e-08" izz="0.00232585" />
    </inertial>
    <visual>
      <origin xyz="0 0 0" rpy="0 0 0" />
      <geometry>
        <mesh filename="package://kuavo_assets/models/biped_s50/meshes/r_foot_roll.STL" />
      </geometry>
      <material name="">
        <color rgba="1 1 1 1" />
      </material>
    </visual>
    <collision>
      <origin rpy="0 0 0" xyz="0.02 0 -0.055" />
      <geometry>
        <box size="0.25 0.1 0.01"/>
      </geometry>
    </collision>
  </link>
  <joint name="leg_r6_joint" type="revolute">
    <origin xyz="0 0 0" rpy="0 0 0" />
    <parent link="leg_r5_link" />
    <child link="leg_r6_link" />
    <axis xyz="1 0 0" />
    <limit lower="-0.349065850398866" upper="0.349065850398866" effort="36.0" velocity="23.0266666666667" />
  </joint>
  <link name="rl_foot_toe">
    <!-- <collision>
      <origin rpy="0 0 0" xyz="0 0 0" />
      <geometry>
        <sphere radius="0.005" />
      </geometry>
    </collision> -->
  </link>
  <joint name="rl_foot_toe_joint" type="fixed">
    <origin xyz="0.142507 0.04773 -0.0595" rpy="0 0 0" />
    <parent link="leg_r6_link" />
    <child link="rl_foot_toe" />
  </joint>
  <link name="rl_foot_heel">
    <!-- <collision>
      <origin rpy="0 0 0" xyz="0 0 0" />
      <geometry>
        <sphere radius="0.005" />
      </geometry>
    </collision> -->
  </link>
  <joint name="rl_foot_heel_joint" type="fixed">
    <origin xyz="-0.10149 0.04773 -0.0595" rpy="0 0 0" />
    <parent link="leg_r6_link" />
    <child link="rl_foot_heel" />
  </joint>
  <link name="rr_foot_toe">
    <!-- <collision>
      <origin rpy="0 0 0" xyz="0 0 0" />
      <geometry>
        <sphere radius="0.005" />
      </geometry>
    </collision> -->
  </link>
  <joint name="rr_foot_toe_joint" type="fixed">
    <origin xyz="0.142507 -0.04773 -0.0595" rpy="0 0 0" />
    <parent link="leg_r6_link" />
    <child link="rr_foot_toe" />
  </joint>
  <link name="rr_foot_heel">
    <!-- <collision>
      <origin rpy="0 0 0" xyz="0 0 0" />
      <geometry>
        <sphere radius="0.005" />
      </geometry>
    </collision> -->
  </link>
  <joint name="rr_foot_heel_joint" type="fixed">
    <origin xyz="-0.10149 -0.04773 -0.0595" rpy="0 0 0" />
    <parent link="leg_r6_link" />
    <child link="rr_foot_heel" />
  </joint>
  <link name="r_foot_toe">
    <!-- <collision>
      <origin rpy="0 0 0" xyz="0 0 0" />
      <geometry>
        <sphere radius="0.005" />
      </geometry>
    </collision> -->
  </link>
  <joint name="r_foot_toe_joint" type="fixed">
    <origin xyz="0.142507 0.0 -0.0595" rpy="0 0 0" />
    <parent link="leg_r6_link" />
    <child link="r_foot_toe" />
  </joint>
  <link name="r_foot_heel">
    <!-- <collision>
      <origin rpy="0 0 0" xyz="0 0 0" />
      <geometry>
        <sphere radius="0.005" />
      </geometry>
    </collision> -->
  </link>
  <joint name="r_foot_heel_joint" type="fixed">
    <origin xyz="-0.10149 0.0 -0.0595" rpy="0 0 0" />
    <parent link="leg_r6_link" />
    <child link="r_foot_heel" />
  </joint>
  <link name="zarm_l1_link">
    <inertial>
      <origin xyz="0.008 -0.00158 0.0036" rpy="0 0 0" />
      <mass value="1.15" />
      <inertia ixx="0.0006" ixy="5e-05" ixz="1e-05" iyy="0.00048" iyz="-6e-05" izz="0.0007" />
    </inertial>
    <visual>
      <origin xyz="0 0 0" rpy="0 0 0" />
      <geometry>
        <mesh filename="package://kuavo_assets/models/biped_s50/meshes/l_arm_pitch.STL" />
      </geometry>
      <material name="">
        <color rgba="1 1 1 1" />
      </material>
    </visual>
  </link>
  <joint name="zarm_l1_joint" type="revolute">
    <origin xyz="-0.0175 0.25886 0.3245" rpy="0 0 0" />
    <parent link="base_link" />
    <child link="zarm_l1_link" />
    <axis xyz="0 1 0" />
    <limit lower="-2.61799387799149" upper="0.523598775598299" effort="100.0" velocity="41.3433333333333" />
  </joint>
  <link name="zarm_l2_link">
    <inertial>
      <origin xyz="0.00144 0.02159 -0.0202" rpy="0 0 0" />
      <mass value="0.226" />
      <inertia ixx="0.0003" ixy="3e-05" ixz="1e-05" iyy="0.00061" iyz="5e-05" izz="0.00057" />
    </inertial>
    <visual>
      <origin xyz="0 0 0" rpy="0 0 0" />
      <geometry>
        <mesh filename="package://kuavo_assets/models/biped_s50/meshes/l_arm_roll.STL" />
      </geometry>
      <material name="">
        <color rgba="1 1 1 1" />
      </material>
    </visual>
    <collision>
      <origin rpy="0 1.57 0" xyz="0.01 0 0"/>
      <geometry>
        <cylinder radius="0.045" length='0.08'/>
      </geometry>
    </collision> 
  </link>
  <joint name="zarm_l2_joint" type="revolute">
    <origin xyz="0 0 0" rpy="0 0 0" />
    <parent link="zarm_l1_link" />
    <child link="zarm_l2_link" />
    <axis xyz="1 0 0" />
    <limit lower="-0.349065850398866" upper="2.0943951023932" effort="50.0" velocity="19.154" />
  </joint>
  <link name="zarm_l3_link">
    <inertial>
      <origin xyz="-0.00157 -3e-05 -0.13318" rpy="0 0 0" />
      <mass value="1.166" />
      <inertia ixx="0.00245" ixy="-1e-05" ixz="-1e-05" iyy="0.0022" iyz="0.0" izz="0.00112" />
    </inertial>
    <visual>
      <origin xyz="0 0 0" rpy="0 0 0" />
      <geometry>
        <mesh filename="package://kuavo_assets/models/biped_s50/meshes/l_arm_yaw.STL" />
      </geometry>
      <material name="">
        <color rgba="1 1 1 1" />
      </material>
    </visual>
    <collision>
      <origin rpy="0 0 0" xyz="0 0 -0.09"/>
      <geometry>
        <cylinder radius="0.04" length='0.062'/>
      </geometry>
    </collision> 
  </link>
  <joint name="zarm_l3_joint" type="revolute">
    <origin xyz="0 0 0" rpy="0 0 0" />
    <parent link="zarm_l2_link" />
    <child link="zarm_l3_link" />
    <axis xyz="0 0 1" />
    <limit lower="-1.5707963267949" upper="1.5707963267949" effort="20.0" velocity="18.84" />
  </joint>
  <link name="zarm_l4_link">
    <inertial>
      <origin xyz="-4e-05 0.0098 -0.05283" rpy="0 0 0" />
      <mass value="0.575" />
      <inertia ixx="0.00098" ixy="0.0" ixz="0.0" iyy="0.00062" iyz="-0.00016" izz="0.00088" />
    </inertial>
    <visual>
      <origin xyz="0 0 0" rpy="0 0 0" />
      <geometry>
        <mesh filename="package://kuavo_assets/models/biped_s50/meshes/l_forearm.STL" />
      </geometry>
      <material name="">
        <color rgba="1 1 1 1" />
      </material>
    </visual>
    <collision>
      <origin rpy="1.57 0 0" xyz="0 0 0"/>
      <geometry>
        <cylinder radius="0.04" length='0.065'/>
      </geometry>
    </collision>
  </link>
  <joint name="zarm_l4_joint" type="revolute">
    <origin xyz="0 0 -0.1646" rpy="0 0 0" />
    <parent link="zarm_l3_link" />
    <child link="zarm_l4_link" />
    <axis xyz="0 1 0" />
    <limit lower="-1.5707963267949" upper="0.0" effort="20.0" velocity="18.84" />
  </joint>
  <link name="zarm_l5_link">
    <inertial>
      <origin xyz="-0.00011 0.00421 -0.11168" rpy="0 0 0" />
      <mass value="0.46" />
      <inertia ixx="0.00077" ixy="0.0" ixz="0.0" iyy="0.0005" iyz="-4e-05" izz="0.00063" />
    </inertial>
    <visual>
      <origin xyz="0 0 0" rpy="0 0 0" />
      <geometry>
        <mesh filename="package://kuavo_assets/models/biped_s50/meshes/l_hand_yaw.STL" />
      </geometry>
      <material name="">
        <color rgba="1 1 1 1" />
      </material>
    </visual>
    <collision>
      <origin rpy="0 0 0" xyz="0 0 0.12"/>
      <geometry>
        <cylinder radius="0.04" length='0.05'/>
      </geometry>
    </collision>  
  </link>
  <joint name="zarm_l5_joint" type="revolute">
    <origin xyz="0 0 0" rpy="0 0 0" />
    <parent link="zarm_l4_link" />
    <child link="zarm_l5_link" />
    <axis xyz="0 0 1" />
    <limit lower="-1.5707963267949" upper="1.5707963267949" effort="6.0" velocity="21.666" />
  </joint>
  <link name="zarm_l6_link">
    <inertial>
      <origin xyz="0.00253 0.00382 -0.05356" rpy="0 0 0" />
      <mass value="0.35" />
      <inertia ixx="0.00023" ixy="0.0" ixz="0.0" iyy="0.00024" iyz="-4e-05" izz="0.00019" />
    </inertial>
    <visual>
      <origin xyz="0 0 0" rpy="0 0 0" />
      <geometry>
        <mesh filename="package://kuavo_assets/models/biped_s50/meshes/l_hand_pitch.STL" />
      </geometry>
      <material name="">
        <color rgba="1 1 1 1" />
      </material>
    </visual>
    <collision>
      <origin rpy="1.57 0 0" xyz="0 0 0.06"/>
      <geometry>
        <cylinder radius="0.028" length='0.05'/>
      </geometry>
    </collision>   
  </link>
  <joint name="zarm_l6_joint" type="revolute">
    <origin xyz="0 0 -0.132050000125748" rpy="0 0 0" />
    <parent link="zarm_l5_link" />
    <child link="zarm_l6_link" />
    <axis xyz="0 1 0" />
    <limit lower="-1.5707963267949" upper="1.5707963267949" effort="6.0" velocity="21.666" />
  </joint>
  <link name="zarm_l7_link">
    <inertial>
      <origin xyz="0.00267 0.00748 -0.07162" rpy="0 0 0" />
      <mass value="0.81" />
      <inertia ixx="0.00117" ixy="2e-05" ixz="0.0" iyy="0.00128" iyz="-2e-05" izz="0.00036" />
    </inertial>
    <visual>
      <origin xyz="0 0 0" rpy="0 0 0" />
      <geometry>
        <mesh filename="package://kuavo_assets/models/biped_s50/meshes/l_hand_roll.STL" />
      </geometry>
      <material name="">
        <color rgba="1 1 1 1" />
      </material>
    </visual>
    <collision>
      <origin rpy="0 1.57 0" xyz="0 0 0"/>
      <geometry>
        <cylinder radius="0.028" length='0.05'/>
      </geometry>
    </collision>  
  </link>
  <joint name="zarm_l7_joint" type="revolute">
    <origin xyz="0 0 -0.0589999999999999" rpy="0 0 0" />
    <parent link="zarm_l6_link" />
    <child link="zarm_l7_link" />
    <axis xyz="1 0 0" />
    <limit lower="-1.5707963267949" upper="1.5707963267949" effort="6.0" velocity="21.666" />
  </joint>
  <link name="zarm_l7_end_effector">
    <collision>
      <origin rpy="0 0 0" xyz="0 0 0" />
      <geometry>
        <sphere radius="0.005" />
      </geometry>
    </collision>
  </link>
  <joint name="zarm_l7_end_effector_joint" type="fixed">
    <origin xyz="0 -0.03 -0.17" rpy="0 0 0" />
    <parent link="zarm_l7_link" />
    <child link="zarm_l7_end_effector" />
  </joint>
  <link name="zarm_r1_link">
    <inertial>
      <origin xyz="0.008 0.00158 -0.0036" rpy="0 0 0" />
      <mass value="1.15" />
      <inertia ixx="0.0006" ixy="-5e-05" ixz="-1e-05" iyy="0.00048" iyz="-6e-05" izz="0.0007" />
    </inertial>
    <visual>
      <origin xyz="0 0 0" rpy="0 0 0" />
      <geometry>
        <mesh filename="package://kuavo_assets/models/biped_s50/meshes/r_arm_pitch.STL" />
      </geometry>
      <material name="">
        <color rgba="1 1 1 1" />
      </material>
    </visual>
  </link>
  <joint name="zarm_r1_joint" type="revolute">
    <origin xyz="-0.0175 -0.25886 0.3245" rpy="0 0 0" />
    <parent link="base_link" />
    <child link="zarm_r1_link" />
    <axis xyz="0 1 0" />
    <limit lower="-2.61799387799149" upper="0.523598775598299" effort="100.0" velocity="41.3433333333333" />
  </joint>
  <link name="zarm_r2_link">
    <inertial>
      <origin xyz="0.00144 -0.02159 -0.02021" rpy="0 0 0" />
      <mass value="0.226" />
      <inertia ixx="0.0003" ixy="-3e-05" ixz="1e-05" iyy="0.00061" iyz="-5e-05" izz="0.00057" />
    </inertial>
    <visual>
      <origin xyz="0 0 0" rpy="0 0 0" />
      <geometry>
        <mesh filename="package://kuavo_assets/models/biped_s50/meshes/r_arm_roll.STL" />
      </geometry>
      <material name="">
        <color rgba="1 1 1 1" />
      </material>
    </visual>
    <collision>
      <origin rpy="0 1.57 0" xyz="0.01 0 0"/>
      <geometry>
        <cylinder radius="0.045" length='0.08'/>
      </geometry>
    </collision>    
  </link>
  <joint name="zarm_r2_joint" type="revolute">
    <origin xyz="0 0 0" rpy="0 0 0" />
    <parent link="zarm_r1_link" />
    <child link="zarm_r2_link" />
    <axis xyz="1 0 0" />
    <limit lower="-2.0943951023932" upper="0.349065850398866" effort="50.0" velocity="19.154" />
  </joint>
  <link name="zarm_r3_link">
    <inertial>
      <origin xyz="-0.00157 3e-05 -0.13318" rpy="0 0 0" />
      <mass value="1.166" />
      <inertia ixx="0.00245" ixy="1e-05" ixz="-1e-05" iyy="0.0022" iyz="0.0" izz="0.00112" />
    </inertial>
    <visual>
      <origin xyz="0 0 0" rpy="0 0 0" />
      <geometry>
        <mesh filename="package://kuavo_assets/models/biped_s50/meshes/r_arm_yaw.STL" />
      </geometry>
      <material name="">
        <color rgba="1 1 1 1" />
      </material>
    </visual>
    <collision>
      <origin rpy="0 0 0" xyz="0 0 -0.09"/>
      <geometry>
        <cylinder radius="0.04" length='0.062'/>
      </geometry>
    </collision>     
  </link>
  <joint name="zarm_r3_joint" type="revolute">
    <origin xyz="0 0 0" rpy="0 0 0" />
    <parent link="zarm_r2_link" />
    <child link="zarm_r3_link" />
    <axis xyz="0 0 1" />
    <limit lower="-1.5707963267949" upper="1.5707963267949" effort="20.0" velocity="18.84" />
  </joint>
  <link name="zarm_r4_link">
    <inertial>
      <origin xyz="-4e-05 -0.0098 -0.05283" rpy="0 0 0" />
      <mass value="0.575" />
      <inertia ixx="0.00098" ixy="0.0" ixz="0.0" iyy="0.00062" iyz="0.00016" izz="0.00088" />
    </inertial>
    <visual>
      <origin xyz="0 0 0" rpy="0 0 0" />
      <geometry>
        <mesh filename="package://kuavo_assets/models/biped_s50/meshes/r_forearm.STL" />
      </geometry>
      <material name="">
        <color rgba="1 1 1 1" />
      </material>
    </visual>
    <collision>
      <origin rpy="1.57 0 0" xyz="0 0 0"/>
      <geometry>
        <cylinder radius="0.04" length='0.065'/>
      </geometry>
    </collision> 
  </link>
  <joint name="zarm_r4_joint" type="revolute">
    <origin xyz="0 0 -0.1646" rpy="0 0 0" />
    <parent link="zarm_r3_link" />
    <child link="zarm_r4_link" />
    <axis xyz="0 1 0" />
    <limit lower="-1.5707963267949" upper="0.0" effort="20.0" velocity="18.84" />
  </joint>
  <link name="zarm_r5_link">
    <inertial>
      <origin xyz="-0.00011 -0.00421 -0.11168" rpy="0 0 0" />
      <mass value="0.46" />
      <inertia ixx="0.00077" ixy="0.0" ixz="0.0" iyy="0.0005" iyz="4e-05" izz="0.00063" />
    </inertial>
    <visual>
      <origin xyz="0 0 0" rpy="0 0 0" />
      <geometry>
        <mesh filename="package://kuavo_assets/models/biped_s50/meshes/r_hand_yaw.STL" />
      </geometry>
      <material name="">
        <color rgba="1 1 1 1" />
      </material>
    </visual>
    <collision>
      <origin rpy="0 0 0" xyz="0 0 0.12"/>
      <geometry>
        <cylinder radius="0.04" length='0.05'/>
      </geometry>
    </collision> 
  </link>
  <joint name="zarm_r5_joint" type="revolute">
    <origin xyz="0 0 0" rpy="0 0 0" />
    <parent link="zarm_r4_link" />
    <child link="zarm_r5_link" />
    <axis xyz="0 0 1" />
    <limit lower="-1.5707963267949" upper="1.5707963267949" effort="6.0" velocity="21.666" />
  </joint>
  <link name="zarm_r6_link">
    <inertial>
      <origin xyz="0.00253 -0.00382 -0.05356" rpy="0 0 0" />
      <mass value="0.35" />
      <inertia ixx="0.00023" ixy="0.0" ixz="0.0" iyy="0.00024" iyz="4e-05" izz="0.00019" />
    </inertial>
    <visual>
      <origin xyz="0 0 0" rpy="0 0 0" />
      <geometry>
        <mesh filename="package://kuavo_assets/models/biped_s50/meshes/r_hand_pitch.STL" />
      </geometry>
      <material name="">
        <color rgba="1 1 1 1" />
      </material>
    </visual>
    <collision>
      <origin rpy="1.57 0 0" xyz="0 0 0.06"/>
      <geometry>
        <cylinder radius="0.028" length='0.05'/>
      </geometry>
    </collision>  
  </link>
  <joint name="zarm_r6_joint" type="revolute">
    <origin xyz="0 0 -0.132050000240097" rpy="0 0 0" />
    <parent link="zarm_r5_link" />
    <child link="zarm_r6_link" />
    <axis xyz="0 1 0" />
    <limit lower="-1.5707963267949" upper="1.5707963267949" effort="6.0" velocity="21.666" />
  </joint>
  <link name="zarm_r7_link">
    <inertial>
      <origin xyz="0.00267 -0.00748 -0.07162" rpy="0 0 0" />
      <mass value="0.81" />
      <inertia ixx="0.00098" ixy="-1e-05" ixz="1e-05" iyy="0.00104" iyz="1e-05" izz="0.00027" />
    </inertial>
    <visual>
      <origin xyz="0 0 0" rpy="0 0 0" />
      <geometry>
        <mesh filename="package://kuavo_assets/models/biped_s50/meshes/r_hand_roll.STL" />
      </geometry>
      <material name="">
        <color rgba="1 1 1 1" />
      </material>
    </visual>
    <collision>
      <origin rpy="0 1.57 0" xyz="0 0 0"/>
      <geometry>
        <cylinder radius="0.028" length='0.05'/>
      </geometry>
    </collision> 
  </link>
  <joint name="zarm_r7_joint" type="revolute">
    <origin xyz="0 0 -0.0589999999999999" rpy="0 0 0" />
    <parent link="zarm_r6_link" />
    <child link="zarm_r7_link" />
    <axis xyz="1 0 0" />
    <limit lower="-1.5707963267949" upper="1.5707963267949" effort="6.0" velocity="21.666" />
  </joint>
  <link name="zarm_r7_end_effector">
    <collision>
      <origin rpy="0 0 0" xyz="0 0 0" />
      <geometry>
        <sphere radius="0.005" />
      </geometry>
    </collision>
  </link>
  <joint name="zarm_r7_end_effector_joint" type="fixed">
    <origin xyz="0 0.03 -0.17" rpy="0 0 0" />
    <parent link="zarm_r7_link" />
    <child link="zarm_r7_end_effector" />
  </joint>
  <link name="zhead_1_link">
    <inertial>
      <origin xyz="0.0 0.01245 -0.02982" rpy="0 0 0" />
      <mass value="0.082" />
      <inertia ixx="7e-05" ixy="0.0" ixz="0.0" iyy="6e-05" iyz="-2e-05" izz="8e-05" />
    </inertial>
    <visual>
      <origin xyz="0 0 0" rpy="0 0 0" />
      <geometry>
        <mesh filename="package://kuavo_assets/models/biped_s50/meshes/head_yaw.STL" />
      </geometry>
      <material name="">
        <color rgba="1 1 1 1" />
      </material>
    </visual>
  </link>
  <joint name="zhead_1_joint" type="revolute">
    <origin xyz="-0.0175 0.0 0.5014" rpy="0 0 0" />
    <parent link="base_link" />
    <child link="zhead_1_link" />
    <axis xyz="0 0 1" />
    <limit lower="-1.5707963267949" upper="1.5707963267949" effort="1.5" velocity="5.23333333333333" />
  </joint>
  <link name="zhead_2_link">
    <inertial>
      <origin xyz="0.01106 0.00069 0.0586" rpy="0 0 0" />
      <mass value="1.379" />
      <inertia ixx="0.003" ixy="1e-05" ixz="0.0003" iyy="0.00301" iyz="5e-05" izz="0.00281" />
    </inertial>
    <visual>
      <origin xyz="0 0 0" rpy="0 0 0" />
      <geometry>
        <mesh filename="package://kuavo_assets/models/biped_s50/meshes/head_pitch.STL" />
      </geometry>
      <material name="">
        <color rgba="1 1 1 1" />
      </material>
    </visual>
  </link>
  <joint name="zhead_2_joint" type="revolute">
    <origin xyz="0 0 0" rpy="0 0 0" />
    <parent link="zhead_1_link" />
    <child link="zhead_2_link" />
    <axis xyz="0 1 0" />
    <limit lower="-0.523598775598299" upper="0.523598775598299" effort="6.0" velocity="9.734" />
  </joint>
  <link name="camera">
    <inertial>
      <origin xyz="-0.04336 -0.01736 -0.01161" rpy="0 0 0" />
      <mass value="0.047" />
      <inertia ixx="0.00065" ixy="0.0" ixz="0.00015" iyy="0.00091" iyz="0.0" izz="0.00105" />
    </inertial>
    <visual>
      <origin xyz="0 0 0" rpy="0 0 0" />
      <geometry>
        <mesh filename="package://kuavo_assets/models/biped_s50/meshes/camera.STL" />
      </geometry>
      <material name="">
        <color rgba="1 1 1 1" />
      </material>
    </visual>
  </link>
  <joint name="camera" type="fixed">
    <origin xyz="0.0919101155958193 0.0175000000022731 0.0617838754768194" rpy="0 0.610865238198013 0" />
    <parent link="zhead_2_link" />
    <child link="camera" />
  </joint>
</robot>
